Traceback (most recent call last):
  File "/home/User/PycharmProjects/PoseEstimationFPHAB/modelundmainfun.py", line 34, in <module>
    node_features, edge_index, _ = train_dataset
  File "/home/User/miniconda3/envs/Myenv/lib/python3.10/site-packages/torch/utils/data/dataset.py", line 412, in __getitem__
    return self.dataset[self.indices[idx]]
  File "/home/User/PycharmProjects/PoseEstimationFPHAB/Mydataset.py", line 48, in __getitem__
    node_features = self.transform(node_features)
  File "/home/User/miniconda3/envs/Myenv/lib/python3.10/site-packages/torchvision/transforms/transforms.py", line 95, in __call__
    img = t(img)
  File "/home/User/miniconda3/envs/Myenv/lib/python3.10/site-packages/torch/nn/modules/module.py", line 1736, in _wrapped_call_impl
    return self._call_impl(*args, **kwargs)
  File "/home/User/miniconda3/envs/Myenv/lib/python3.10/site-packages/torch/nn/modules/module.py", line 1747, in _call_impl
    return forward_call(*args, **kwargs)
  File "/home/User/miniconda3/envs/Myenv/lib/python3.10/site-packages/torchvision/transforms/transforms.py", line 277, in forward
    return F.normalize(tensor, self.mean, self.std, self.inplace)
  File "/home/User/miniconda3/envs/Myenv/lib/python3.10/site-packages/torchvision/transforms/functional.py", line 350, in normalize
    return F_t.normalize(tensor, mean=mean, std=std, inplace=inplace)
  File "/home/User/miniconda3/envs/Myenv/lib/python3.10/site-packages/torchvision/transforms/_functional_tensor.py", line 928, in normalize
    return tensor.sub_(mean).div_(std)
RuntimeError: output with shape [1, 224, 224] doesn't match the broadcast shape [3, 224, 224]